Workbook

Sheet 学生成绩
A1: 浙江水利水电学院春学期大一体育课程评分计算模板
A2: 此表格用于自动计算身体素质成绩或课程成绩 注：性别必填/选，橙色框内请勿修改，立定跳远单位为cm，800/1000米4分5秒请填4.05
A3: 序号 | B3: 学号 | C3: 姓名 | D3: 性别* | E3: 班级 | F3: 平时成绩 | G3: 阳光长跑 | H3: 身体素质得分 | I3: 身体素质 | R3: 课程总分 | S3: 备注
F4: 满分100 | G4: 满分100 | I4: 引体向上 仰卧起坐 | J4: 成绩 | K4: 中长跑 | L4: 成绩 | M4: 50米 | N4: 成绩 | O4: 立定跳远 | P4: 成绩 | Q4: 身体素质得分
A5: 1 | B5: 2023b11001 | C5: 林凯 | D5: 男 | E5: 软工23-1 | H5: =Q5 -> 58.5 | I5: 2 | J5: =IF(I5<>"",IF(D5="男",HLOOKUP(I5,各项评分标准!$12:$14,3,1),HLOOKUP(I5,各项评分标准!$13:$14,2,1)),0) -> 20 | K5: 3.54 | L5: =IF(K5<>"",IF(D5="男",HLOOKUP(K5,各项评分标准!$16:$18,3,1),HLOOKUP(K5,各项评分标准!$17:$18,2,1)),0) -> 74 | M5: 7.55 | N5: =IF(M5<>"",IF(D5="男",HLOOKUP(M5,各项评分标准!$4:$6,3,1),HLOOKUP(M5,各项评分标准!$5:$6,2,1)),0) -> 74 | O5: 223 | P5: =IF(O5<>"",IF(D5="男",HLOOKUP(O5,各项评分标准!$8:$10,3,1),HLOOKUP(O5,各项评分标准!$9:$10,2,1)),0) -> 66 | Q5: =(J5+L5+N5+P5)/4 -> 58.5 | R5: =F5*10%+G5*10%+H5*80% -> 46.8
A6: 2 | B6: 2023b11002 | C6: 焦磊 | D6: 男 | E6: 软工23-1 | H6: =Q6 -> 70 | I6: 5 | J6: =IF(I6<>"",IF(D6="男",HLOOKUP(I6,各项评分标准!$12:$14,3,1),HLOOKUP(I6,各项评分标准!$13:$14,2,1)),0) -> 50 | K6: 3.59 | L6: =IF(K6<>"",IF(D6="男",HLOOKUP(K6,各项评分标准!$16:$18,3,1),HLOOKUP(K6,各项评分标准!$17:$18,2,1)),0) -> 72 | M6: 7.11 | N6: =IF(M6<>"",IF(D6="男",HLOOKUP(M6,各项评分标准!$4:$6,3,1),HLOOKUP(M6,各项评分标准!$5:$6,2,1)),0) -> 78 | O6: 250 | P6: =IF(O6<>"",IF(D6="男",HLOOKUP(O6,各项评分标准!$8:$10,3,1),HLOOKUP(O6,各项评分标准!$9:$10,2,1)),0) -> 80 | Q6: =(J6+L6+N6+P6)/4 -> 70 | R6: =F6*10%+G6*10%+H6*80% -> 56
A7: 3 | B7: 2023b11003 | C7: 叶珂语 | D7: 女 | E7: 软工23-1 | H7: =Q7 -> 71.5 | I7: 41 | J7: =IF(I7<>"",IF(D7="男",HLOOKUP(I7,各项评分标准!$12:$14,3,1),HLOOKUP(I7,各项评分标准!$13:$14,2,1)),0) -> 74 | K7: 4.3 | L7: =IF(K7<>"",IF(D7="男",HLOOKUP(K7,各项评分标准!$16:$18,3,1),HLOOKUP(K7,各项评分标准!$17:$18,2,1)),0) -> 60 | M7: 8.97 | N7: =IF(M7<>"",IF(D7="男",HLOOKUP(M7,各项评分标准!$4:$6,3,1),HLOOKUP(M7,各项评分标准!$5:$6,2,1)),0) -> 72 | O7: 184 | P7: =IF(O7<>"",IF(D7="男",HLOOKUP(O7,各项评分标准!$8:$10,3,1),HLOOKUP(O7,各项评分标准!$9:$10,2,1)),0) -> 80 | Q7: =(J7+L7+N7+P7)/4 -> 71.5 | R7: =F7*10%+G7*10%+H7*80% -> 57.2
A8: 4 | B8: 2023b11004 | C8: 赵杜炜 | D8: 男 | E8: 软工23-1 | H8: =Q8 -> 61.5 | I8: 5 | J8: =IF(I8<>"",IF(D8="男",HLOOKUP(I8,各项评分标准!$12:$14,3,1),HLOOKUP(I8,各项评分标准!$13:$14,2,1)),0) -> 50 | K8: 4.25 | L8: =IF(K8<>"",IF(D8="男",HLOOKUP(K8,各项评分标准!$16:$18,3,1),HLOOKUP(K8,各项评分标准!$17:$18,2,1)),0) -> 62 | M8: 7.69 | N8: =IF(M8<>"",IF(D8="男",HLOOKUP(M8,各项评分标准!$4:$6,3,1),HLOOKUP(M8,各项评分标准!$5:$6,2,1)),0) -> 74 | O8: 212 | P8: =IF(O8<>"",IF(D8="男",HLOOKUP(O8,各项评分标准!$8:$10,3,1),HLOOKUP(O8,各项评分标准!$9:$10,2,1)),0) -> 60 | Q8: =(J8+L8+N8+P8)/4 -> 61.5 | R8: =F8*10%+G8*10%+H8*80% -> 49.2
A9: 5 | B9: 2023b11005 | C9: 余睿翔 | D9: 男 | E9: 软工23-1 | H9: =Q9 -> 82.75 | I9: 11 | J9: =IF(I9<>"",IF(D9="男",HLOOKUP(I9,各项评分标准!$12:$14,3,1),HLOOKUP(I9,各项评分标准!$13:$14,2,1)),0) -> 101 | K9: 4.01 | L9: =IF(K9<>"",IF(D9="男",HLOOKUP(K9,各项评分标准!$16:$18,3,1),HLOOKUP(K9,各项评分标准!$17:$18,2,1)),0) -> 70 | M9: 7.07 | N9: =IF(M9<>"",IF(D9="男",HLOOKUP(M9,各项评分标准!$4:$6,3,1),HLOOKUP(M9,各项评分标准!$5:$6,2,1)),0) -> 80 | O9: 253 | P9: =IF(O9<>"",IF(D9="男",HLOOKUP(O9,各项评分标准!$8:$10,3,1),HLOOKUP(O9,各项评分标准!$9:$10,2,1)),0) -> 80 | Q9: =(J9+L9+N9+P9)/4 -> 82.75 | R9: =F9*10%+G9*10%+H9*80% -> 66.2
A10: 6 | B10: 2023b11006 | C10: 罗家康 | D10: 男 | E10: 软工23-1 | H10: =Q10 -> 0 | J10: =IF(I10<>"",IF(D10="男",HLOOKUP(I10,各项评分标准!$12:$14,3,1),HLOOKUP(I10,各项评分标准!$13:$14,2,1)),0) -> 0 | L10: =IF(K10<>"",IF(D10="男",HLOOKUP(K10,各项评分标准!$16:$18,3,1),HLOOKUP(K10,各项评分标准!$17:$18,2,1)),0) -> 0 | N10: =IF(M10<>"",IF(D10="男",HLOOKUP(M10,各项评分标准!$4:$6,3,1),HLOOKUP(M10,各项评分标准!$5:$6,2,1)),0) -> 0 | P10: =IF(O10<>"",IF(D10="男",HLOOKUP(O10,各项评分标准!$8:$10,3,1),HLOOKUP(O10,各项评分标准!$9:$10,2,1)),0) -> 0 | Q10: =(J10+L10+N10+P10)/4 -> 0 | R10: =F10*10%+G10*10%+H10*80% -> 0
A11: 7 | B11: 2023b11007 | C11: 吴乐乐 | D11: 男 | E11: 软工23-1 | H11: =Q11 -> 82.75 | I11: 19 | J11: =IF(I11<>"",IF(D11="男",HLOOKUP(I11,各项评分标准!$12:$14,3,1),HLOOKUP(I11,各项评分标准!$13:$14,2,1)),0) -> 109 | K11: 3.52 | L11: =IF(K11<>"",IF(D11="男",HLOOKUP(K11,各项评分标准!$16:$18,3,1),HLOOKUP(K11,各项评分标准!$17:$18,2,1)),0) -> 74 | M11: 7.53 | N11: =IF(M11<>"",IF(D11="男",HLOOKUP(M11,各项评分标准!$4:$6,3,1),HLOOKUP(M11,各项评分标准!$5:$6,2,1)),0) -> 74 | O11: 240 | P11: =IF(O11<>"",IF(D11="男",HLOOKUP(O11,各项评分标准!$8:$10,3,1),HLOOKUP(O11,各项评分标准!$9:$10,2,1)),0) -> 74 | Q11: =(J11+L11+N11+P11)/4 -> 82.75 | R11: =F11*10%+G11*10%+H11*80% -> 66.2
A12: 8 | B12: 2023b11008 | C12: 林雅琼 | D12: 女 | E12: 软工23-1 | H12: =Q12 -> 83.5 | I12: 47 | J12: =IF(I12<>"",IF(D12="男",HLOOKUP(I12,各项评分标准!$12:$14,3,1),HLOOKUP(I12,各项评分标准!$13:$14,2,1)),0) -> 80 | K12: 3.51 | L12: =IF(K12<>"",IF(D12="男",HLOOKUP(K12,各项评分标准!$16:$18,3,1),HLOOKUP(K12,各项评分标准!$17:$18,2,1)),0) -> 76 | M12: 8.39 | N12: =IF(M12<>"",IF(D12="男",HLOOKUP(M12,各项评分标准!$4:$6,3,1),HLOOKUP(M12,各项评分标准!$5:$6,2,1)),0) -> 78 | O12: 208 | P12: =IF(O12<>"",IF(D12="男",HLOOKUP(O12,各项评分标准!$8:$10,3,1),HLOOKUP(O12,各项评分标准!$9:$10,2,1)),0) -> 100 | Q12: =(J12+L12+N12+P12)/4 -> 83.5 | R12: =F12*10%+G12*10%+H12*80% -> 66.8
A13: 9 | B13: 2023b11009 | C13: 沈德涵 | D13: 男 | E13: 软工23-1 | H13: =Q13 -> 0 | J13: =IF(I13<>"",IF(D13="男",HLOOKUP(I13,各项评分标准!$12:$14,3,1),HLOOKUP(I13,各项评分标准!$13:$14,2,1)),0) -> 0 | L13: =IF(K13<>"",IF(D13="男",HLOOKUP(K13,各项评分标准!$16:$18,3,1),HLOOKUP(K13,各项评分标准!$17:$18,2,1)),0) -> 0 | N13: =IF(M13<>"",IF(D13="男",HLOOKUP(M13,各项评分标准!$4:$6,3,1),HLOOKUP(M13,各项评分标准!$5:$6,2,1)),0) -> 0 | P13: =IF(O13<>"",IF(D13="男",HLOOKUP(O13,各项评分标准!$8:$10,3,1),HLOOKUP(O13,各项评分标准!$9:$10,2,1)),0) -> 0 | Q13: =(J13+L13+N13+P13)/4 -> 0 | R13: =F13*10%+G13*10%+H13*80% -> 0
A14: 10 | B14: 2023b11010 | C14: 洪方祺 | D14: 男 | E14: 软工23-1 | H14: =Q14 -> 74.5 | I14: 10 | J14: =IF(I14<>"",IF(D14="男",HLOOKUP(I14,各项评分标准!$12:$14,3,1),HLOOKUP(I14,各项评分标准!$13:$14,2,1)),0) -> 100 | K14: 4.12 | L14: =IF(K14<>"",IF(D14="男",HLOOKUP(K14,各项评分标准!$16:$18,3,1),HLOOKUP(K14,各项评分标准!$17:$18,2,1)),0) -> 66 | M14: 7.83 | N14: =IF(M14<>"",IF(D14="男",HLOOKUP(M14,各项评分标准!$4:$6,3,1),HLOOKUP(M14,各项评分标准!$5:$6,2,1)),0) -> 72 | O14: 210 | P14: =IF(O14<>"",IF(D14="男",HLOOKUP(O14,各项评分标准!$8:$10,3,1),HLOOKUP(O14,各项评分标准!$9:$10,2,1)),0) -> 60 | Q14: =(J14+L14+N14+P14)/4 -> 74.5 | R14: =F14*10%+G14*10%+H14*80% -> 59.6
A15: 11 | B15: 2023b11011 | C15: 高鑫垒 | D15: 男 | E15: 软工23-1 | H15: =Q15 -> 50 | I15: 2 | J15: =IF(I15<>"",IF(D15="男",HLOOKUP(I15,各项评分标准!$12:$14,3,1),HLOOKUP(I15,各项评分标准!$13:$14,2,1)),0) -> 20 | K15: 4.47 | L15: =IF(K15<>"",IF(D15="男",HLOOKUP(K15,各项评分标准!$16:$18,3,1),HLOOKUP(K15,各项评分标准!$17:$18,2,1)),0) -> 50 | M15: 8.13 | N15: =IF(M15<>"",IF(D15="男",HLOOKUP(M15,各项评分标准!$4:$6,3,1),HLOOKUP(M15,各项评分标准!$5:$6,2,1)),0) -> 68 | O15: 216 | P15: =IF(O15<>"",IF(D15="男",HLOOKUP(O15,各项评分标准!$8:$10,3,1),HLOOKUP(O15,各项评分标准!$9:$10,2,1)),0) -> 62 | Q15: =(J15+L15+N15+P15)/4 -> 50 | R15: =F15*10%+G15*10%+H15*80% -> 40
A16: 12 | B16: 2023b11012 | C16: 叶晓临 | D16: 男 | E16: 软工23-1 | H16: =Q16 -> 50.5 | I16: 1 | J16: =IF(I16<>"",IF(D16="男",HLOOKUP(I16,各项评分标准!$12:$14,3,1),HLOOKUP(I16,各项评分标准!$13:$14,2,1)),0) -> 10 | K16: 4.29 | L16: =IF(K16<>"",IF(D16="男",HLOOKUP(K16,各项评分标准!$16:$18,3,1),HLOOKUP(K16,各项评分标准!$17:$18,2,1)),0) -> 60 | M16: 8.13 | N16: =IF(M16<>"",IF(D16="男",HLOOKUP(M16,各项评分标准!$4:$6,3,1),HLOOKUP(M16,各项评分标准!$5:$6,2,1)),0) -> 68 | O16: 218 | P16: =IF(O16<>"",IF(D16="男",HLOOKUP(O16,各项评分标准!$8:$10,3,1),HLOOKUP(O16,各项评分标准!$9:$10,2,1)),0) -> 64 | Q16: =(J16+L16+N16+P16)/4 -> 50.5 | R16: =F16*10%+G16*10%+H16*80% -> 40.4
A17: 13 | B17: 2023b11013 | C17: 郑子龙 | D17: 男 | E17: 软工23-1 | H17: =Q17 -> 80.75 | I17: 17 | J17: =IF(I17<>"",IF(D17="男",HLOOKUP(I17,各项评分标准!$12:$14,3,1),HLOOKUP(I17,各项评分标准!$13:$14,2,1)),0) -> 107 | K17: 3.49 | L17: =IF(K17<>"",IF(D17="男",HLOOKUP(K17,各项评分标准!$16:$18,3,1),HLOOKUP(K17,各项评分标准!$17:$18,2,1)),0) -> 76 | M17: 7.53 | N17: =IF(M17<>"",IF(D17="男",HLOOKUP(M17,各项评分标准!$4:$6,3,1),HLOOKUP(M17,各项评分标准!$5:$6,2,1)),0) -> 74 | O17: 222 | P17: =IF(O17<>"",IF(D17="男",HLOOKUP(O17,各项评分标准!$8:$10,3,1),HLOOKUP(O17,各项评分标准!$9:$10,2,1)),0) -> 66 | Q17: =(J17+L17+N17+P17)/4 -> 80.75 | R17: =F17*10%+G17*10%+H17*80% -> 64.6
A18: 14 | B18: 2023b11014 | C18: 金晓晨 | D18: 女 | E18: 软工23-1 | H18: =Q18 -> 88.5 | I18: 53 | J18: =IF(I18<>"",IF(D18="男",HLOOKUP(I18,各项评分标准!$12:$14,3,1),HLOOKUP(I18,各项评分标准!$13:$14,2,1)),0) -> 90 | K18: 3.13 | L18: =IF(K18<>"",IF(D18="男",HLOOKUP(K18,各项评分标准!$16:$18,3,1),HLOOKUP(K18,各项评分标准!$17:$18,2,1)),0) -> 100 | M18: 8.83 | N18: =IF(M18<>"",IF(D18="男",HLOOKUP(M18,各项评分标准!$4:$6,3,1),HLOOKUP(M18,各项评分标准!$5:$6,2,1)),0) -> 74 | O18: 200 | P18: =IF(O18<>"",IF(D18="男",HLOOKUP(O18,各项评分标准!$8:$10,3,1),HLOOKUP(O18,各项评分标准!$9:$10,2,1)),0) -> 90 | Q18: =(J18+L18+N18+P18)/4 -> 88.5 | R18: =F18*10%+G18*10%+H18*80% -> 70.8
A19: 15 | B19: 2023b11015 | C19: 汪黎明 | D19: 男 | E19: 软工23-1 | H19: =Q19 -> 57 | I19: 2 | J19: =IF(I19<>"",IF(D19="男",HLOOKUP(I19,各项评分标准!$12:$14,3,1),HLOOKUP(I19,各项评分标准!$13:$14,2,1)),0) -> 20 | K19: 4.14 | L19: =IF(K19<>"",IF(D19="男",HLOOKUP(K19,各项评分标准!$16:$18,3,1),HLOOKUP(K19,各项评分标准!$17:$18,2,1)),0) -> 66 | M19: 7.82 | N19: =IF(M19<>"",IF(D19="男",HLOOKUP(M19,各项评分标准!$4:$6,3,1),HLOOKUP(M19,各项评分标准!$5:$6,2,1)),0) -> 72 | O19: 232 | P19: =IF(O19<>"",IF(D19="男",HLOOKUP(O19,各项评分标准!$8:$10,3,1),HLOOKUP(O19,各项评分标准!$9:$10,2,1)),0) -> 70 | Q19: =(J19+L19+N19+P19)/4 -> 57 | R19: =F19*10%+G19*10%+H19*80% -> 45.6
A20: 16 | B20: 2023b11016 | C20: 袁佳炜 | D20: 男 | E20: 软工23-1 | H20: =Q20 -> 65 | I20: 4 | J20: =IF(I20<>"",IF(D20="男",HLOOKUP(I20,各项评分标准!$12:$14,3,1),HLOOKUP(I20,各项评分标准!$13:$14,2,1)),0) -> 40 | K20: 3.33 | L20: =IF(K20<>"",IF(D20="男",HLOOKUP(K20,各项评分标准!$16:$18,3,1),HLOOKUP(K20,各项评分标准!$17:$18,2,1)),0) -> 80 | M20: 7.06 | N20: =IF(M20<>"",IF(D20="男",HLOOKUP(M20,各项评分标准!$4:$6,3,1),HLOOKUP(M20,各项评分标准!$5:$6,2,1)),0) -> 80 | O20: 210 | P20: =IF(O20<>"",IF(D20="男",HLOOKUP(O20,各项评分标准!$8:$10,3,1),HLOOKUP(O20,各项评分标准!$9:$10,2,1)),0) -> 60 | Q20: =(J20+L20+N20+P20)/4 -> 65 | R20: =F20*10%+G20*10%+H20*80% -> 52
A21: 17 | B21: 2023b11017 | C21: 章淦越 | D21: 男 | E21: 软工23-1 | H21: =Q21 -> 73.5 | I21: 8 | J21: =IF(I21<>"",IF(D21="男",HLOOKUP(I21,各项评分标准!$12:$14,3,1),HLOOKUP(I21,各项评分标准!$13:$14,2,1)),0) -> 80 | K21: 3.56 | L21: =IF(K21<>"",IF(D21="男",HLOOKUP(K21,各项评分标准!$16:$18,3,1),HLOOKUP(K21,各项评分标准!$17:$18,2,1)),0) -> 72 | M21: 7.37 | N21: =IF(M21<>"",IF(D21="男",HLOOKUP(M21,各项评分标准!$4:$6,3,1),HLOOKUP(M21,各项评分标准!$5:$6,2,1)),0) -> 76 | O21: 222 | P21: =IF(O21<>"",IF(D21="男",HLOOKUP(O21,各项评分标准!$8:$10,3,1),HLOOKUP(O21,各项评分标准!$9:$10,2,1)),0) -> 66 | Q21: =(J21+L21+N21+P21)/4 -> 73.5 | R21: =F21*10%+G21*10%+H21*80% -> 58.8
A22: 18 | B22: 2023b11018 | C22: 林恩特 | D22: 男 | E22: 软工23-1 | H22: =Q22 -> 71.75 | I22: 4 | J22: =IF(I22<>"",IF(D22="男",HLOOKUP(I22,各项评分标准!$12:$14,3,1),HLOOKUP(I22,各项评分标准!$13:$14,2,1)),0) -> 40 | K22: 3.58 | L22: =IF(K22<>"",IF(D22="男",HLOOKUP(K22,各项评分标准!$16:$18,3,1),HLOOKUP(K22,各项评分标准!$17:$18,2,1)),0) -> 72 | M22: 6.83 | N22: =IF(M22<>"",IF(D22="男",HLOOKUP(M22,各项评分标准!$4:$6,3,1),HLOOKUP(M22,各项评分标准!$5:$6,2,1)),0) -> 90 | O22: 258 | P22: =IF(O22<>"",IF(D22="男",HLOOKUP(O22,各项评分标准!$8:$10,3,1),HLOOKUP(O22,各项评分标准!$9:$10,2,1)),0) -> 85 | Q22: =(J22+L22+N22+P22)/4 -> 71.75 | R22: =F22*10%+G22*10%+H22*80% -> 57.4
A23: 19 | B23: 2023b11019 | C23: 孙毅捷 | D23: 男 | E23: 软工23-1 | H23: =Q23 -> 77.5 | I23: 10 | J23: =IF(I23<>"",IF(D23="男",HLOOKUP(I23,各项评分标准!$12:$14,3,1),HLOOKUP(I23,各项评分标准!$13:$14,2,1)),0) -> 100 | K23: 3.57 | L23: =IF(K23<>"",IF(D23="男",HLOOKUP(K23,各项评分标准!$16:$18,3,1),HLOOKUP(K23,各项评分标准!$17:$18,2,1)),0) -> 72 | M23: 7.7 | N23: =IF(M23<>"",IF(D23="男",HLOOKUP(M23,各项评分标准!$4:$6,3,1),HLOOKUP(M23,各项评分标准!$5:$6,2,1)),0) -> 72 | O23: 223 | P23: =IF(O23<>"",IF(D23="男",HLOOKUP(O23,各项评分标准!$8:$10,3,1),HLOOKUP(O23,各项评分标准!$9:$10,2,1)),0) -> 66 | Q23: =(J23+L23+N23+P23)/4 -> 77.5 | R23: =F23*10%+G23*10%+H23*80% -> 62
A24: 20 | B24: 2023b11020 | C24: 屠子滢 | D24: 女 | E24: 软工23-1 | H24: =Q24 -> 89.5 | I24: 55 | J24: =IF(I24<>"",IF(D24="男",HLOOKUP(I24,各项评分标准!$12:$14,3,1),HLOOKUP(I24,各项评分标准!$13:$14,2,1)),0) -> 95 | K24: 3.23 | L24: =IF(K24<>"",IF(D24="男",HLOOKUP(K24,各项评分标准!$16:$18,3,1),HLOOKUP(K24,各项评分标准!$17:$18,2,1)),0) -> 90 | M24: 8.35 | N24: =IF(M24<>"",IF(D24="男",HLOOKUP(M24,各项评分标准!$4:$6,3,1),HLOOKUP(M24,各项评分标准!$5:$6,2,1)),0) -> 78 | O24: 205 | P24: =IF(O24<>"",IF(D24="男",HLOOKUP(O24,各项评分标准!$8:$10,3,1),HLOOKUP(O24,各项评分标准!$9:$10,2,1)),0) -> 95 | Q24: =(J24+L24+N24+P24)/4 -> 89.5 | R24: =F24*10%+G24*10%+H24*80% -> 71.6
A25: 21 | B25: 2023b11021 | C25: 祝浩然 | D25: 男 | E25: 软工23-1 | H25: =Q25 -> 75 | I25: 10 | J25: =IF(I25<>"",IF(D25="男",HLOOKUP(I25,各项评分标准!$12:$14,3,1),HLOOKUP(I25,各项评分标准!$13:$14,2,1)),0) -> 100 | K25: 4.26 | L25: =IF(K25<>"",IF(D25="男",HLOOKUP(K25,各项评分标准!$16:$18,3,1),HLOOKUP(K25,各项评分标准!$17:$18,2,1)),0) -> 60 | M25: 8.02 | N25: =IF(M25<>"",IF(D25="男",HLOOKUP(M25,各项评分标准!$4:$6,3,1),HLOOKUP(M25,各项评分标准!$5:$6,2,1)),0) -> 70 | O25: 230 | P25: =IF(O25<>"",IF(D25="男",HLOOKUP(O25,各项评分标准!$8:$10,3,1),HLOOKUP(O25,各项评分标准!$9:$10,2,1)),0) -> 70 | Q25: =(J25+L25+N25+P25)/4 -> 75 | R25: =F25*10%+G25*10%+H25*80% -> 60
... A34: 30 | B34: 2023b11030 | C34: 杨仕强 | D34: 男 | E34: 软工23-1 | H34: =Q34 -> 51 | I34: 0 | J34: =IF(I34<>"",IF(D34="男",HLOOKUP(I34,各项评分标准!$12:$14,3,1),HLOOKUP(I34,各项评分标准!$13:$14,2,1)),0) -> 0 | K34: 4.3 | L34: =IF(K34<>"",IF(D34="男",HLOOKUP(K34,各项评分标准!$16:$18,3,1),HLOOKUP(K34,各项评分标准!$17:$18,2,1)),0) -> 60 | M34: 7.76 | N34: =IF(M34<>"",IF(D34="男",HLOOKUP(M34,各项评分标准!$4:$6,3,1),HLOOKUP(M34,各项评分标准!$5:$6,2,1)),0) -> 72 | O34: 235 | P34: =IF(O34<>"",IF(D34="男",HLOOKUP(O34,各项评分标准!$8:$10,3,1),HLOOKUP(O34,各项评分标准!$9:$10,2,1)),0) -> 72 | Q34: =(J34+L34+N34+P34)/4 -> 51 | R34: =F34*10%+G34*10%+H34*80% -> 40.8
A35: 31 | B35: 2023b21016 | C35: 邓依仟 | D35: 女 | E35: 软工23-1 | H35: =Q35 -> 34.5 | I35: 20 | J35: =IF(I35<>"",IF(D35="男",HLOOKUP(I35,各项评分标准!$12:$14,3,1),HLOOKUP(I35,各项评分标准!$13:$14,2,1)),0) -> 20 | L35: =IF(K35<>"",IF(D35="男",HLOOKUP(K35,各项评分标准!$16:$18,3,1),HLOOKUP(K35,各项评分标准!$17:$18,2,1)),0) -> 0 | M35: 10.44 | N35: =IF(M35<>"",IF(D35="男",HLOOKUP(M35,各项评分标准!$4:$6,3,1),HLOOKUP(M35,各项评分标准!$5:$6,2,1)),0) -> 50 | O35: 165 | P35: =IF(O35<>"",IF(D35="男",HLOOKUP(O35,各项评分标准!$8:$10,3,1),HLOOKUP(O35,各项评分标准!$9:$10,2,1)),0) -> 68 | Q35: =(J35+L35+N35+P35)/4 -> 34.5 | R35: =F35*10%+G35*10%+H35*80% -> 27.6
A36: 32 | B36: 2022b11077 | C36: 黄馨娴 | D36: 女 | E36: 软工23-1 | H36: =Q36 -> 67.5 | I36: 49 | J36: =IF(I36<>"",IF(D36="男",HLOOKUP(I36,各项评分标准!$12:$14,3,1),HLOOKUP(I36,各项评分标准!$13:$14,2,1)),0) -> 80 | K36: 4.4 | L36: =IF(K36<>"",IF(D36="男",HLOOKUP(K36,各项评分标准!$16:$18,3,1),HLOOKUP(K36,各项评分标准!$17:$18,2,1)),0) -> 50 | M36: 9.58 | N36: =IF(M36<>"",IF(D36="男",HLOOKUP(M36,各项评分标准!$4:$6,3,1),HLOOKUP(M36,各项评分标准!$5:$6,2,1)),0) -> 66 | O36: 175 | P36: =IF(O36<>"",IF(D36="男",HLOOKUP(O36,各项评分标准!$8:$10,3,1),HLOOKUP(O36,各项评分标准!$9:$10,2,1)),0) -> 74 | Q36: =(J36+L36+N36+P36)/4 -> 67.5 | R36: =F36*10%+G36*10%+H36*80% -> 54
A37: 1 | B37: 2023b11031 | C37: 杨宇胜 | D37: 男 | E37: 软工23-2 | H37: =Q37 -> 82.25 | I37: 11 | J37: =IF(I37<>"",IF(D37="男",HLOOKUP(I37,各项评分标准!$12:$14,3,1),HLOOKUP(I37,各项评分标准!$13:$14,2,1)),0) -> 101 | K37: 4.04 | L37: =IF(K37<>"",IF(D37="男",HLOOKUP(K37,各项评分标准!$16:$18,3,1),HLOOKUP(K37,各项评分标准!$17:$18,2,1)),0) -> 70 | M37: 7 | N37: =IF(M37<>"",IF(D37="男",HLOOKUP(M37,各项评分标准!$4:$6,3,1),HLOOKUP(M37,各项评分标准!$5:$6,2,1)),0) -> 80 | O37: 248 | P37: =IF(O37<>"",IF(D37="男",HLOOKUP(O37,各项评分标准!$8:$10,3,1),HLOOKUP(O37,各项评分标准!$9:$10,2,1)),0) -> 78 | Q37: =(J37+L37+N37+P37)/4 -> 82.25 | R37: =F37*10%+G37*10%+H37*80% -> 65.8
A38: 2 | B38: 2023b11032 | C38: 李意民 | D38: 男 | E38: 软工23-2 | H38: =Q38 -> 80 | I38: 6 | J38: =IF(I38<>"",IF(D38="男",HLOOKUP(I38,各项评分标准!$12:$14,3,1),HLOOKUP(I38,各项评分标准!$13:$14,2,1)),0) -> 60 | K38: 3.29 | L38: =IF(K38<>"",IF(D38="男",HLOOKUP(K38,各项评分标准!$16:$18,3,1),HLOOKUP(K38,各项评分标准!$17:$18,2,1)),0) -> 85 | M38: 6.86 | N38: =IF(M38<>"",IF(D38="男",HLOOKUP(M38,各项评分标准!$4:$6,3,1),HLOOKUP(M38,各项评分标准!$5:$6,2,1)),0) -> 90 | O38: 264 | P38: =IF(O38<>"",IF(D38="男",HLOOKUP(O38,各项评分标准!$8:$10,3,1),HLOOKUP(O38,各项评分标准!$9:$10,2,1)),0) -> 85 | Q38: =(J38+L38+N38+P38)/4 -> 80 | R38: =F38*10%+G38*10%+H38*80% -> 64
A39: 3 | B39: 2023b11033 | C39: 袁潇雅 | D39: 女 | E39: 软工23-2 | H39: =Q39 -> 66.5 | I39: 27 | J39: =IF(I39<>"",IF(D39="男",HLOOKUP(I39,各项评分标准!$12:$14,3,1),HLOOKUP(I39,各项评分标准!$13:$14,2,1)),0) -> 60 | K39: 4.06 | L39: =IF(K39<>"",IF(D39="男",HLOOKUP(K39,各项评分标准!$16:$18,3,1),HLOOKUP(K39,各项评分标准!$17:$18,2,1)),0) -> 70 | M39: 9.35 | N39: =IF(M39<>"",IF(D39="男",HLOOKUP(M39,各项评分标准!$4:$6,3,1),HLOOKUP(M39,各项评分标准!$5:$6,2,1)),0) -> 68 | O39: 165 | P39: =IF(O39<>"",IF(D39="男",HLOOKUP(O39,各项评分标准!$8:$10,3,1),HLOOKUP(O39,各项评分标准!$9:$10,2,1)),0) -> 68 | Q39: =(J39+L39+N39+P39)/4 -> 66.5 | R39: =F39*10%+G39*10%+H39*80% -> 53.2
A40: 4 | B40: 2023b11034 | C40: 黄哲远 | D40: 男 | E40: 软工23-2 | H40: =Q40 -> 50 | I40: 0 | J40: =IF(I40<>"",IF(D40="男",HLOOKUP(I40,各项评分标准!$12:$14,3,1),HLOOKUP(I40,各项评分标准!$13:$14,2,1)),0) -> 0 | K40: 4.1 | L40: =IF(K40<>"",IF(D40="男",HLOOKUP(K40,各项评分标准!$16:$18,3,1),HLOOKUP(K40,各项评分标准!$17:$18,2,1)),0) -> 68 | M40: 7.78 | N40: =IF(M40<>"",IF(D40="男",HLOOKUP(M40,各项评分标准!$4:$6,3,1),HLOOKUP(M40,各项评分标准!$5:$6,2,1)),0) -> 72 | O40: 210 | P40: =IF(O40<>"",IF(D40="男",HLOOKUP(O40,各项评分标准!$8:$10,3,1),HLOOKUP(O40,各项评分标准!$9:$10,2,1)),0) -> 60 | Q40: =(J40+L40+N40+P40)/4 -> 50 | R40: =F40*10%+G40*10%+H40*80% -> 40
A41: 5 | B41: 2023b11035 | C41: 张道欢 | D41: 男 | E41: 软工23-2 | H41: =Q41 -> 82.75 | I41: 15 | J41: =IF(I41<>"",IF(D41="男",HLOOKUP(I41,各项评分标准!$12:$14,3,1),HLOOKUP(I41,各项评分标准!$13:$14,2,1)),0) -> 105 | K41: 4.05 | L41: =IF(K41<>"",IF(D41="男",HLOOKUP(K41,各项评分标准!$16:$18,3,1),HLOOKUP(K41,各项评分标准!$17:$18,2,1)),0) -> 70 | M41: 7.36 | N41: =IF(M41<>"",IF(D41="男",HLOOKUP(M41,各项评分标准!$4:$6,3,1),HLOOKUP(M41,各项评分标准!$5:$6,2,1)),0) -> 76 | O41: 253 | P41: =IF(O41<>"",IF(D41="男",HLOOKUP(O41,各项评分标准!$8:$10,3,1),HLOOKUP(O41,各项评分标准!$9:$10,2,1)),0) -> 80 | Q41: =(J41+L41+N41+P41)/4 -> 82.75 | R41: =F41*10%+G41*10%+H41*80% -> 66.2
A42: 6 | B42: 2023b11036 | C42: 邵宇鹏 | D42: 男 | E42: 软工23-2 | H42: =Q42 -> 77.75 | I42: 13 | J42: =IF(I42<>"",IF(D42="男",HLOOKUP(I42,各项评分标准!$12:$14,3,1),HLOOKUP(I42,各项评分标准!$13:$14,2,1)),0) -> 103 | K42: 4.24 | L42: =IF(K42<>"",IF(D42="男",HLOOKUP(K42,各项评分标准!$16:$18,3,1),HLOOKUP(K42,各项评分标准!$17:$18,2,1)),0) -> 62 | M42: 7.36 | N42: =IF(M42<>"",IF(D42="男",HLOOKUP(M42,各项评分标准!$4:$6,3,1),HLOOKUP(M42,各项评分标准!$5:$6,2,1)),0) -> 76 | O42: 232 | P42: =IF(O42<>"",IF(D42="男",HLOOKUP(O42,各项评分标准!$8:$10,3,1),HLOOKUP(O42,各项评分标准!$9:$10,2,1)),0) -> 70 | Q42: =(J42+L42+N42+P42)/4 -> 77.75 | R42: =F42*10%+G42*10%+H42*80% -> 62.2
A43: 7 | B43: 2023b11037 | C43: 栾逸晨 | D43: 男 | E43: 软工23-2 | H43: =Q43 -> 69.5 | I43: 7 | J43: =IF(I43<>"",IF(D43="男",HLOOKUP(I43,各项评分标准!$12:$14,3,1),HLOOKUP(I43,各项评分标准!$13:$14,2,1)),0) -> 70 | K43: 4.27 | L43: =IF(K43<>"",IF(D43="男",HLOOKUP(K43,各项评分标准!$16:$18,3,1),HLOOKUP(K43,各项评分标准!$17:$18,2,1)),0) -> 60 | M43: 7.44 | N43: =IF(M43<>"",IF(D43="男",HLOOKUP(M43,各项评分标准!$4:$6,3,1),HLOOKUP(M43,各项评分标准!$5:$6,2,1)),0) -> 76 | O43: 235 | P43: =IF(O43<>"",IF(D43="男",HLOOKUP(O43,各项评分标准!$8:$10,3,1),HLOOKUP(O43,各项评分标准!$9:$10,2,1)),0) -> 72 | Q43: =(J43+L43+N43+P43)/4 -> 69.5 | R43: =F43*10%+G43*10%+H43*80% -> 55.6
A44: 8 | B44: 2023b11038 | C44: 周俊琪 | D44: 男 | E44: 软工23-2 | H44: =Q44 -> 38 | I44: 0 | J44: =IF(I44<>"",IF(D44="男",HLOOKUP(I44,各项评分标准!$12:$14,3,1),HLOOKUP(I44,各项评分标准!$13:$14,2,1)),0) -> 0 | K44: 5.35 | L44: =IF(K44<>"",IF(D44="男",HLOOKUP(K44,各项评分标准!$16:$18,3,1),HLOOKUP(K44,各项评分标准!$17:$18,2,1)),0) -> 20 | M44: 8.28 | N44: =IF(M44<>"",IF(D44="男",HLOOKUP(M44,各项评分标准!$4:$6,3,1),HLOOKUP(M44,各项评分标准!$5:$6,2,1)),0) -> 68 | O44: 221 | P44: =IF(O44<>"",IF(D44="男",HLOOKUP(O44,各项评分标准!$8:$10,3,1),HLOOKUP(O44,各项评分标准!$9:$10,2,1)),0) -> 64 | Q44: =(J44+L44+N44+P44)/4 -> 38 | R44: =F44*10%+G44*10%+H44*80% -> 30.4
A45: 9 | B45: 2023b11039 | C45: 俞君豪 | D45: 男 | E45: 软工23-2 | H45: =Q45 -> 39.5 | I45: 0 | J45: =IF(I45<>"",IF(D45="男",HLOOKUP(I45,各项评分标准!$12:$14,3,1),HLOOKUP(I45,各项评分标准!$13:$14,2,1)),0) -> 0 | K45: 4.36 | L45: =IF(K45<>"",IF(D45="男",HLOOKUP(K45,各项评分标准!$16:$18,3,1),HLOOKUP(K45,各项评分标准!$17:$18,2,1)),0) -> 50 | M45: 8.12 | N45: =IF(M45<>"",IF(D45="男",HLOOKUP(M45,各项评分标准!$4:$6,3,1),HLOOKUP(M45,各项评分标准!$5:$6,2,1)),0) -> 68 | O45: 200 | P45: =IF(O45<>"",IF(D45="男",HLOOKUP(O45,各项评分标准!$8:$10,3,1),HLOOKUP(O45,各项评分标准!$9:$10,2,1)),0) -> 40 | Q45: =(J45+L45+N45+P45)/4 -> 39.5 | R45: =F45*10%+G45*10%+H45*80% -> 31.6
A46: 10 | B46: 2023b11040 | C46: 叶鑫晖 | D46: 男 | E46: 软工23-2 | H46: =Q46 -> 33 | I46: 0 | J46: =IF(I46<>"",IF(D46="男",HLOOKUP(I46,各项评分标准!$12:$14,3,1),HLOOKUP(I46,各项评分标准!$13:$14,2,1)),0) -> 0 | K46: 5.27 | L46: =IF(K46<>"",IF(D46="男",HLOOKUP(K46,各项评分标准!$16:$18,3,1),HLOOKUP(K46,各项评分标准!$17:$18,2,1)),0) -> 30 | M46: 7.87 | N46: =IF(M46<>"",IF(D46="男",HLOOKUP(M46,各项评分标准!$4:$6,3,1),HLOOKUP(M46,各项评分标准!$5:$6,2,1)),0) -> 72 | O46: 198 | P46: =IF(O46<>"",IF(D46="男",HLOOKUP(O46,各项评分标准!$8:$10,3,1),HLOOKUP(O46,各项评分标准!$9:$10,2,1)),0) -> 30 | Q46: =(J46+L46+N46+P46)/4 -> 33 | R46: =F46*10%+G46*10%+H46*80% -> 26.4
A47: 11 | B47: 2023b11041 | C47: 陈寒旭 | D47: 男 | E47: 软工23-2 | H47: =Q47 -> 46 | I47: 0 | J47: =IF(I47<>"",IF(D47="男",HLOOKUP(I47,各项评分标准!$12:$14,3,1),HLOOKUP(I47,各项评分标准!$13:$14,2,1)),0) -> 0 | K47: 4.46 | L47: =IF(K47<>"",IF(D47="男",HLOOKUP(K47,各项评分标准!$16:$18,3,1),HLOOKUP(K47,各项评分标准!$17:$18,2,1)),0) -> 50 | M47: 7.82 | N47: =IF(M47<>"",IF(D47="男",HLOOKUP(M47,各项评分标准!$4:$6,3,1),HLOOKUP(M47,各项评分标准!$5:$6,2,1)),0) -> 72 | O47: 217 | P47: =IF(O47<>"",IF(D47="男",HLOOKUP(O47,各项评分标准!$8:$10,3,1),HLOOKUP(O47,各项评分标准!$9:$10,2,1)),0) -> 62 | Q47: =(J47+L47+N47+P47)/4 -> 46 | R47: =F47*10%+G47*10%+H47*80% -> 36.8
... A59: 23 | B59: 2023b11053 | C59: 高帆 | D59: 女 | E59: 软工23-2 | H59: =Q59 -> 61.5 | I59: 31 | J59: =IF(I59<>"",IF(D59="男",HLOOKUP(I59,各项评分标准!$12:$14,3,1),HLOOKUP(I59,各项评分标准!$13:$14,2,1)),0) -> 64 | K59: 4.38 | L59: =IF(K59<>"",IF(D59="男",HLOOKUP(K59,各项评分标准!$16:$18,3,1),HLOOKUP(K59,各项评分标准!$17:$18,2,1)),0) -> 50 | M59: 9.76 | N59: =IF(M59<>"",IF(D59="男",HLOOKUP(M59,各项评分标准!$4:$6,3,1),HLOOKUP(M59,各项评分标准!$5:$6,2,1)),0) -> 64 | O59: 166 | P59: =IF(O59<>"",IF(D59="男",HLOOKUP(O59,各项评分标准!$8:$10,3,1),HLOOKUP(O59,各项评分标准!$9:$10,2,1)),0) -> 68 | Q59: =(J59+L59+N59+P59)/4 -> 61.5 | R59: =F59*10%+G59*10%+H59*80% -> 49.2
...

Sheet 各项评分标准
A1: 该页为各项成绩评分标准，请勿随意更改，以免导致Excel无法计算
A4: 50米（男） | B4: 0 | C4: 6.691 | D4: 6.791 | E4: 6.891 | F4: 6.991 | G4: 7.091 | H4: 7.291 | I4: 7.491 | J4: 7.691 | K4: 7.891 | L4: 8.091 | M4: 8.291 | N4: 8.491 | O4: 8.691 | P4: 8.891 | Q4: 9.091 | R4: 9.291 | S4: 9.491 | T4: 9.691 | U4: 9.891 | V4: 10.091
A5: 50米（女） | B5: 0 | C5: 7.491 | D5: 7.591 | E5: 7.691 | F5: 7.991 | G5: 8.291 | H5: 8.491 | I5: 8.691 | J5: 8.891 | K5: 9.091 | L5: 9.291 | M5: 9.491 | N5: 9.691 | O5: 9.891 | P5: 10.091 | Q5: 10.291 | R5: 10.491 | S5: 10.691 | T5: 10.891 | U5: 11.091 | V5: 11.291
A6: 成绩 | B6: 100 | C6: 95 | D6: 90 | E6: 85 | F6: 80 | G6: 78 | H6: 76 | I6: 74 | J6: 72 | K6: 70 | L6: 68 | M6: 66 | N6: 64 | O6: 62 | P6: 60 | Q6: 50 | R6: 40 | S6: 30 | T6: 20 | U6: 10 | V6: 0
A8: 立定跳远（男） | B8: 0 | C8: 185 | D8: 190 | E8: 195 | F8: 200 | G8: 205 | H8: 210 | I8: 214 | J8: 218 | K8: 222 | L8: 226 | M8: 230 | N8: 234 | O8: 238 | P8: 242 | Q8: 246 | R8: 250 | S8: 258 | T8: 265 | U8: 270 | V8: 275
A9: 立定跳远（女） | B9: 0 | C9: 127 | D9: 132 | E9: 137 | F9: 142 | G9: 147 | H9: 152 | I9: 155 | J9: 158 | K9: 161 | L9: 164 | M9: 167 | N9: 170 | O9: 173 | P9: 176 | Q9: 179 | R9: 182 | S9: 189 | T9: 196 | U9: 202 | V9: 208
A10: 成绩 | B10: 0 | C10: 10 | D10: 20 | E10: 30 | F10: 40 | G10: 50 | H10: 60 | I10: 62 | J10: 64 | K10: 66 | L10: 68 | M10: 70 | N10: 72 | O10: 74 | P10: 76 | Q10: 78 | R10: 80 | S10: 85 | T10: 90 | U10: 95 | V10: 100
A12: 引体向上 | B12: 0 | C12: 1 | D12: 2 | E12: 3 | F12: 4 | G12: 5 | H12: 6 | M12: 7 | R12: 8 | T12: 9 | V12: 10 | W12: 11 | X12: 12 | Y12: 13 | Z12: 14 | AA12: 15 | AB12: 16 | AC12: 17 | AD12: 18 | AE12: 19 | AF12: 20
A13: 仰卧起坐 | B13: 0 | C13: 17 | D13: 19 | E13: 21 | F13: 23 | G13: 25 | H13: 27 | I13: 29 | J13: 31 | K13: 33 | L13: 35 | M13: 37 | N13: 39 | O13: 41 | P13: 43 | Q13: 45 | R13: 47 | S13: 50 | T13: 53 | U13: 55 | V13: 57
A14: 成绩 | B14: 0 | C14: 10 | D14: 20 | E14: 30 | F14: 40 | G14: 50 | H14: 60 | I14: 62 | J14: 64 | K14: 66 | L14: 68 | M14: 70 | N14: 72 | O14: 74 | P14: 76 | Q14: 78 | R14: 80 | S14: 85 | T14: 90 | U14: 95 | V14: 100 | W14: 101 | X14: 102 | Y14: 103 | Z14: 104 | AA14: 105 | AB14: 106 | AC14: 107 | AD14: 108 | AE14: 109 | AF14: 110
A16: 耐力跑（男） | B16: 0 | C16: 3.151 | D16: 3.201 | E16: 3.251 | F16: 3.321 | G16: 3.401 | H16: 3.451 | I16: 3.501 | J16: 3.551 | K16: 4.001 | L16: 4.051 | M16: 4.101 | N16: 4.151 | O16: 4.201 | P16: 4.251 | Q16: 4.301 | R16: 4.501 | S16: 5.101 | T16: 5.301 | U16: 5.501 | V16: 6.101
A17: 耐力跑（女） | B17: 0 | C17: 3.161 | D17: 3.221 | E17: 3.281 | F17: 3.351 | G17: 3.421 | H17: 3.471 | I17: 3.521 | J17: 3.571 | K17: 4.021 | L17: 4.071 | M17: 4.121 | N17: 4.171 | O17: 4.221 | P17: 4.271 | Q17: 4.321 | R17: 4.421 | S17: 4.521 | T17: 5.021 | U17: 5.121 | V17: 5.221
A18: 成绩 | B18: 100 | C18: 95 | D18: 90 | E18: 85 | F18: 80 | G18: 78 | H18: 76 | I18: 74 | J18: 72 | K18: 70 | L18: 68 | M18: 66 | N18: 64 | O18: 62 | P18: 60 | Q18: 50 | R18: 40 | S18: 30 | T18: 20 | U18: 10 | V18: 0
A31: 男生各单项素质指标评分表
A32: 目 | C32: 肺活量 | E32: 50米跑 | G32: 坐位体前屈 | I32: 立定跳远 | K32: 引体向上 | M32: 1000米跑
C33: （单位：毫升） | E33: （单位：秒） | G33: （单位：厘米） | I33: （单位：厘米） | K33: （单位：次） | M33: （单位：分·秒）
B34: 得分 | C34: 大一 | D34: 大三 | E34: 大一 | F34: 大三 | G34: 大一 | H34: 大三 | I34: 大一 | J34: 大三 | K34: 大一 | L34: 大三 | M34: 大一 | N34: 大三
C35: 大二 | D35: 大四 | E35: 大二 | F35: 大四 | G35: 大二 | H35: 大四 | I35: 大二 | J35: 大四 | K35: 大二 | L35: 大四 | M35: 大二 | N35: 大四
A36: 优秀 | B36: 100 | C36: 5040 | D36: 5140 | E36: 6.7 | F36: 6.6 | G36: 24.9 | H36: 25.1 | I36: 273 | J36: 275 | K36: 19 | L36: 20 | M36: 3'17" | N36: 3'15"
B37: 95 | C37: 4920 | D37: 5020 | E37: 6.8 | F37: 6.7 | G37: 23.1 | H37: 23.3 | I37: 268 | J37: 270 | K37: 18 | L37: 19 | M37: 3'22" | N37: 3'20"
B38: 90 | C38: 4800 | D38: 4900 | E38: 6.9 | F38: 6.8 | G38: 21.3 | H38: 21.5 | I38: 263 | J38: 265 | K38: 17 | L38: 18 | M38: 3'27" | N38: 3'25"
A39: 良好 | B39: 85 | C39: 4550 | D39: 4650 | E39: 7 | F39: 6.9 | G39: 19.5 | H39: 19.9 | I39: 256 | J39: 258 | K39: 16 | L39: 17 | M39: 3'34" | N39: 3'32"
B40: 80 | C40: 4300 | D40: 4400 | E40: 7.1 | F40: 7 | G40: 17.7 | H40: 18.2 | I40: 248 | J40: 250 | K40: 15 | L40: 16 | M40: 3'42" | N40: 3'40"
A41: 及格 | B41: 78 | C41: 4180 | D41: 4280 | E41: 7.3 | F41: 7.2 | G41: 16.3 | H41: 16.8 | I41: 244 | J41: 246 | M41: 3'47" | N41: 3'45"
B42: 76 | C42: 4060 | D42: 4160 | E42: 7.5 | F42: 7.4 | G42: 14.9 | H42: 15.4 | I42: 240 | J42: 242 | K42: 14 | L42: 15 | M42: 3'52" | N42: 3'50"
B43: 74 | C43: 3940 | D43: 4040 | E43: 7.7 | F43: 7.6 | G43: 13.5 | H43: 14 | I43: 236 | J43: 238 | M43: 3'57" | N43: 3'55"
B44: 72 | C44: 3820 | D44: 3920 | E44: 7.9 | F44: 7.8 | G44: 12.1 | H44: 12.6 | I44: 232 | J44: 234 | K44: 13 | L44: 14 | M44: 4'02" | N44: 4'00"
B45: 70 | C45: 3700 | D45: 3800 | E45: 8.1 | F45: 8 | G45: 10.7 | H45: 11.2 | I45: 228 | J45: 230 | M45: 4'07" | N45: 4'05"
B46: 68 | C46: 3580 | D46: 3680 | E46: 8.3 | F46: 8.2 | G46: 9.3 | H46: 9.8 | I46: 224 | J46: 226 | K46: 12 | L46: 13 | M46: 4'12" | N46: 4'10"
B47: 66 | C47: 3460 | D47: 3560 | E47: 8.5 | F47: 8.4 | G47: 7.9 | H47: 8.4 | I47: 220 | J47: 222 | M47: 4'17" | N47: 4'15"
B48: 64 | C48: 3340 | D48: 3440 | E48: 8.7 | F48: 8.6 | G48: 6.5 | H48: 7 | I48: 216 | J48: 218 | K48: 11 | L48: 12 | M48: 4'22" | N48: 4'20"
B49: 62 | C49: 3220 | D49: 3320 | E49: 8.9 | F49: 8.8 | G49: 5.1 | H49: 5.6 | I49: 212 | J49: 214 | M49: 4'27" | N49: 4'25"
B50: 60 | C50: 3100 | D50: 3200 | E50: 9.1 | F50: 9 | G50: 3.7 | H50: 4.2 | I50: 208 | J50: 210 | K50: 10 | L50: 11 | M50: 4'32" | N50: 4'30"
A51: 不及格 | B51: 50 | C51: 2940 | D51: 3030 | E51: 9.3 | F51: 9.2 | G51: 2.7 | H51: 3.2 | I51: 203 | J51: 205 | K51: 9 | L51: 10 | M51: 4'52" | N51: 4'50"
B52: 40 | C52: 2780 | D52: 2860 | E52: 9.5 | F52: 9.4 | G52: 1.7 | H52: 2.2 | I52: 198 | J52: 200 | K52: 8 | L52: 9 | M52: 5'12" | N52: 5'10"
B53: 30 | C53: 2620 | D53: 2690 | E53: 9.7 | F53: 9.6 | G53: 0.7 | H53: 1.2 | I53: 193 | J53: 195 | K53: 7 | L53: 8 | M53: 5'32" | N53: 5'30"
B54: 20 | C54: 2460 | D54: 2520 | E54: 9.9 | F54: 9.8 | G54: -0.3 | H54: 0.2 | I54: 188 | J54: 190 | K54: 6 | L54: 7 | M54: 5'52" | N54: 5'50"
B55: 10 | C55: 2300 | D55: 2350 | E55: 10.1 | F55: 10 | G55: -1.3 | H55: -0.8 | I55: 183 | J55: 185 | K55: 5 | L55: 6 | M55: 6'12" | N55: 6'10"
A58: 女生各单项素质指标评分表
A59: 目 | C59: 肺活量 | E59: 50米跑 | G59: 坐位体前屈 | I59: 立定跳远 | K59: 仰卧起坐 | M59: 800米跑
...
